Workbook

Sheet كل التخصصات
A1: 1 | B1: 2 | C1: 3 | D1: 4 | E1: 5 | F1: 6 | G1: 7 | H1: 8 | I1: 9 | J1: 10 | K1: 11 | L1: 12 | M1: 13 | N1: 14 | O1: 15
A2: الرقم | B2: الموضوع | C2: الأستاذ المشرف | D2: الرتبة | E2: اسم الطالب الأول | F2: اسم الطالب الثاني | G2: رئيس اللجنة | H2: الرتبة2 | I2: العضو المناقش | J2: الرتبة3 | K2: الشعبة | L2: التخصص | M2: تاريخ المناقشة | N2: التوقيت | O2: المكان
A3: 11001 | B3: بلاغة الأبنية الصرفية في النص القرآني – آيات المنافقين أنموذجا – | C3: بلقنيشي علي | D3: أستاذ محاضر أ | E3: واضح حسيبة | F3: // | G3: مرضي مصطفى | H3: أستاذ التعليم العالي | I3: عياد آمال | J3: أستاذ التعليم العالي | K3: دراسات لغوية | L3: لسانيات الخطاب
A4: 11002 | B4: أسلوب النهي بين التركيب والدلالة في القرٱن الكربم | C4: بلقاسم عيسى | D4: أستاذ التعليم العالي | E4: بن حامد أمينة | F4: // | G4: بالول أحمد | H4: أستاذ التعليم العالي | I4: احميدة مدني | J4: أستاذ التعليم العالي | K4: دراسات لغوية | L4: لسانيات الخطاب
A5: 11003 | B5: ما التعجبية بين الدلالة والتركيب في القرٱن الكريم | C5: بلقاسم عيسى | D5: أستاذ التعليم العالي | E5: درقاوي وئام | F5: // | G5: ميس سعاد | H5: أستاذ التعليم العالي | I5: طيبي نعيمة | J5: أستاذ التعليم العالي | K5: دراسات لغوية | L5: لسانيات الخطاب
A6: 11004 | B6: دلالة اسم المفعول في القرآن الكريم سورة البقرة انموذجا | C6: بلقاسم عيسى | D6: أستاذ التعليم العالي | E6: بن طراد العيد | F6: بن قراد أحمد | G6: حدوارة عمر | H6: أستاذ التعليم العالي | I6: يعقوب الزهرة | J6: أستاذ محاضر - ب - | K6: دراسات لغوية | L6: لسانيات الخطاب
A7: 11005 | B7: دلالة التربية الروحية في القرآن الكريم ( سورة لقمان أنموذجا ) | C7: بلقاسم عيسى | D7: أستاذ التعليم العالي | E7: بن جامعة ميمونة | F7: // | G7: يعقوب الزهرة | H7: أستاذ محاضر - ب - | I7: ميس سعاد | J7: أستاذ التعليم العالي | K7: دراسات لغوية | L7: لسانيات الخطاب
A8: 11006 | B8: المنزع العقلي في كتاب دلائل الإعجاز لعبد القاهر الجرحاني | C8: عزوز ميلود | D8: أستاذ التعليم العالي | E8: قاسيمي الحسني يسرى | F8: قصاب إكرام | G8: سبع بلمرسلي | H8: أستاذ التعليم العالي | I8: عرابي غالية | J8: أستاذ التعليم العالي | K8: دراسات لغوية | L8: لسانيات الخطاب
A9: 11007 | B9: بلاغة الصمت في مخاطبات النفري | C9: عزوز ميلود | D9: أستاذ التعليم العالي | E9: فاطمي جلول | F9: // | G9: نجادي بوعمامة | H9: أستاذ التعليم العالي | I9: طيبي نعيمة | J9: أستاذ التعليم العالي | K9: دراسات لغوية | L9: لسانيات الخطاب
A10: 11008 | B10: التلوث اللساني في خطاب المقالات العلمية المنشورة في مجلة فصل الخطاب نماذج مختارة | C10: عزوز ميلود | D10: أستاذ التعليم العالي | E10: ياسيني نصيرة | F10: مداح منال | G10: بن شريف محمد | H10: أستاذ التعليم العالي | I10: زمام نبيلة | J10: أستاذ التعليم العالي | K10: دراسات لغوية | L10: لسانيات الخطاب
A11: 11009 | B11: هندسة الخطاب التعليمي الاِفتراضي وتداولية أفعال التحفيز نظرية كيلر على عينة من الطلبة الجامعيين | C11: بن جلول مختار | D11: أستاذ التعليم العالي | E11: عابد عبد الجليل | F11: // | G11: حدوارة عمر | H11: أستاذ التعليم العالي | I11: قوتال فضيلة | J11: أستاذ التعليم العالي | K11: دراسات لغوية | L11: لسانيات الخطاب
A12: 11010 | B12: بنيات الخطاب الأنثوي في النص القرآني - خطابات مريم عليها السلام أنموذجا - | C12: بن جلول مختار | D12: أستاذ التعليم العالي | E12: بوسنة رزيقة | F12: مصطفاوي مختارية | G12: يحياوي عامر | H12: أستاذ التعليم العالي | I12: طيبي نعيمة | J12: أستاذ التعليم العالي | K12: دراسات لغوية | L12: لسانيات الخطاب
A13: 11011 | B13: لغة الخطاب التواصلي في الجامعة الجزائرية قسم اللغة والأدب العربي أنموذجا | C13: قوتال فضيلة | D13: أستاذ التعليم العالي | E13: محمودي ماريا | F13: // | G13: العامي حفيظة | H13: أستاذ التعليم العالي | I13: طيبي نعيمة | J13: أستاذ محاضر - ب - | K13: دراسات لغوية | L13: لسانيات الخطاب
A14: 11012 | B14: مصطلحات لسانيات النص وتحليل الخطاب دراسة تقويمية لمعجم المصطلحات الأساسية في لسانيات النص وتحليل الخطاب نعمان بوقرة | C14: ميس سعاد | D14: أستاذ التعليم العالي | E14: لحمر خديجة | F14: غول أحلام | G14: بوهنوش فاطمة | H14: أستاذ التعليم العالي | I14: عياد آمال | J14: أستاذ التعليم العالي | K14: دراسات لغوية | L14: لسانيات الخطاب
... A55: 21004 | B55: مرجعيات المتخيل الشعري في شعر "عبد الله حمادي" | C55: شريفي فاطمة | D55: أستاذ التعليم العالي | E55: يحي مونية | F55: مناد لطيفة | G55: بوزيان أحمد | H55: أستاذ التعليم العالي | I55: شريط رابح | J55: أستاذ محاضر - ب - | K55: دراسات أدبية | L55: أدب حديث ومعاصر
A56: 21005 | B56: حضور المرأة الصوفية في الرواية الجوائرية المعاصرة اِختيار نموذج | C56: شريفي فاطمة | D56: أستاذ التعليم العالي | E56: بوشعيب زهية | G56: كبريت علي | H56: أستاذ التعليم العالي | I56: بولخراص محمد | J56: أستاذ محاضر - ب - | K56: دراسات أدبية | L56: أدب حديث ومعاصر
A57: 21006 | B57: التيمات الدلالية في روايات دان براون | C57: شريفي فاطمة | D57: أستاذ التعليم العالي | E57: زيتوني سعدية | F57: رمضاني جميلة | G57: شريط رابح | H57: أستاذ التعليم العالي | I57: عطاء الله التاصر | J57: أستاذ التعليم العالي | K57: دراسات أدبية | L57: أدب حديث ومعاصر
A58: 21007 | B58: توظيف الخطاب الديني في الشعر الحديث. الجواهري أنموذجا | C58: جمال صالحي | E58: بلحمري زهرة | F58: كراكرية مليكة | G58: معازيز أبوبكر | H58: أستاذ التعليم العالي | I58: مداني علي | J58: أستاذ محاضر - أ - | K58: دراسات أدبية | L58: أدب حديث ومعاصر
A59: 21008 | B59: صورة الآخر في الرحلة الجزائريةالمعاصرة "جنائن الشرق الملتهبة رحلة في بلاد الصقالبة" ل سعيدخطيبي أنموذجا | C59: يوسفي يوسف | D59: أستاذ التعليم العالي | E59: دين رزنية | F59: قادري إكرام | G59: حاج علي ليلى | H59: أستاذ التعليم العالي | I59: بلكحل العالية | J59: أستاذ محاضر - أ - | K59: دراسات أدبية | L59: أدب حديث ومعاصر
A60: 21009 | B60: تداخل الاجناس الأدبية في أدب الرحلة "رحلة ابن حمادوش "أنموذجا | C60: يوسفي يوسف | D60: أستاذ التعليم العالي | E60: عامري معزوزة | F60: سهايلية عبد المالك | G60: كبريت علي | H60: أستاذ التعليم العالي | I60: دبيح محمد | J60: أستاذ التعليم العالي | K60: دراسات أدبية | L60: أدب حديث ومعاصر
A61: 21010 | B61: التجريب في رواية هوس لحميدة العياشي | C61: محمد مزيلط | E61: قصير مروى | F61: قلولة كريمة | G61: دبيح محمد | H61: أستاذ التعليم العالي | I61: مكيكة محمد جواد | J61: أستاذ التعليم العالي | K61: دراسات أدبية | L61: أدب حديث ومعاصر
A62: 21011 | B62: البنية السردية لرواية زمن القلب لمحمد العالي عرعار | C62: محمد مزيلط | E62: يوسف نصيرة | F62: رايس روميساء | G62: سعيد بلعربي لخضر | H62: أستاذ محاضر - ب - | I62: باقل دنيا | J62: أستاذ التعليم العالي | K62: دراسات أدبية | L62: أدب حديث ومعاصر
A63: 21012 | B63: الشخصية التراثية في المسرح الجزائري الحديث (ولد عبد الرحمن كاكي أنموذجا) | C63: مداني علي | D63: أستاذ التعليم العالي | E63: بوجلطي إكرام | F63: شنافة مريم | G63: يوسفي يوسف | H63: أستاذ محاضر - أ - | I63: باقل دنيا | J63: أستاذ التعليم العالي | K63: دراسات أدبية | L63: أدب حديث ومعاصر
A64: 21013 | B64: صورة فلسطين في ألمانيا بالعربي الموجه للطفل -الهوية و الانتماء | C64: باقل دنيا | D64: أستاذ التعليم العالي | E64: كاري إيمان | F64: موسى سميرة | G64: موازبي ربيع | H64: أستاذ محاضر - ب - | I64: نعار محمد | J64: أستاذ محاضر - أ - | K64: دراسات أدبية | L64: أدب حديث ومعاصر
A65: 21014 | B65: الابعاد الفنية في أدب الاطفال عند خديجة /مقاربة في الرؤيا و التشكيل | C65: باقل دنيا | D65: أستاذ التعليم العالي | E65: بن عيسى حنان | F65: بن حوس أسماء | G65: جمال الين عبد الهادي | H65: أستاذ محاضر - ب - | I65: موازبي ربيع | J65: أستاذ محاضر - ب - | K65: دراسات أدبية | L65: أدب حديث ومعاصر
A66: 21015 | B66: ثنائية الألم والأمل عند الطفل الفلسطيني من خلال أعمال خديجة حيدورة | C66: باقل دنيا | D66: أستاذ التعليم العالي | E66: لعلى حنان | F66: بوعمرة دليلة | G66: بلمسعود قدور | H66: أستاذ محاضر - أ - | I66: حاج علي ليلى | J66: أستاذ محاضر - ب - | K66: دراسات أدبية | L66: أدب حديث ومعاصر
A67: 21016 | B67: الانساق المعرفية والمرجعيات الثقافية في رواية " أنا وحاييم" الحبيب السايح | C67: عبددو رابح | D67: أستاذ محاضر أ | E67: بن عبيد سمرة | F67: دحو فاطمة | G67: بولحراص محمد | H67: أستاذ محاضر - أ - | I67: موازبي ربيع | J67: أستاذ محاضر - أ - | K67: دراسات أدبية | L67: أدب حديث ومعاصر
A68: 21017 | B68: جمالية التشكيل المشهدي في الشعر العربي المعاصر مقاربة أسلومشهدية | C68: جمال الدين عبد الهادي | E68: عابد فاطمة الوهرة | F68: قدور عائشة | G68: مكيكة محمد جواد | H68: أستاذ محاضر - ب - | I68: بن سحنون عابد | J68: أستاذ محاضر - أ - | K68: دراسات أدبية | L68: أدب حديث ومعاصر
A69: 21018 | B69: المثقف والصراع الإيديولوجي في روايات بشير مفتي | C69: شريط رابج | D69: أستاذ محاضر أ | E69: قداري ماجدة حليمة | F69: عمران إيمان | G69: بلمهل عبد الهادي | H69: أستاذ محاضر - أ - | I69: تركي أمحمد | J69: أستاذ محاضر - أ - | K69: دراسات أدبية | L69: أدب حديث ومعاصر
A70: 21019 | B70: هامشية المثقف ورهانات السّلطة في الرواية الجزائرية قراءة في رواية قصيد في التذلل لطاهر وطار | C70: شريط رابج | D70: أستاذ محاضر أ | E70: عوف كوثر | F70: مقران إيمان | G70: بلعجين سفيان | H70: أستاذ التعليم العالي | I70: عطاء الله الناصر | J70: أستاذ التعليم العالي | K70: دراسات أدبية | L70: أدب حديث ومعاصر
A71: 21020 | B71: البنيات الأسطورية في الشعر العربي الحديث السياب أنموذجا | C71: خروبي بلقاسم | D71: أستاذ التعليم العالي | E71: سعيدات الحاجة عودة | F71: لدرع بشرى | G71: بلمهل عبد الهادي | H71: أستاذ التعليم العالي | I71: موازبي ربيع | J71: أستاذ التعليم العالي | K71: دراسات أدبية | L71: أدب حديث ومعاصر
A72: 31001 | B72: ( قراءة في مختارات من ديوان الخنساءعلى ضوء المنهج النفسي | C72: بوزيدي محمد | D72: أستاذ محاضر أ | E72: زمام سمراء | F72: رواب فاطمية الزهرة | G72: زروقي عبد القادر | H72: أستاذ التعليم العالي | I72: بلمهل عبد الهادي | J72: أستاذ التعليم العالي | K72: دراسات نقدية | L72: نقد حديث ومعاصر
A73: 31002 | B73: إشكالية الكتابة النسوية في النقد العربي المعاصر بحث عن الذات أم تأسيس للمركز | C73: صوالح محمد | E73: بلاق أسماء | F73: بن زهرة سهام | G73: عدة قادة | H73: أستاذ التعليم العالي | I73: بولخراص محمد | J73: أستاذ التعليم العالي | K73: دراسات نقدية | L73: نقد حديث ومعاصر
A74: 31003 | B74: سؤال المنهج في الفكر النقدي العربي المعاصر عبد الملك مرتاض | C74: صوالح محمد | E74: جراد رشيدة | F74: بلطرش صبرينة | G74: قوتال فضيلة | H74: أستاذ التعليم العالي | I74: قرور معاشو | J74: أستاذ التعليم العالي | K74: دراسات نقدية | L74: نقد حديث ومعاصر
A75: 31004 | B75: شعرية النوستالجيا (الحنين).من قراءة الحنين إلى قراءة المشاهدة.نماذج من الشعر المعاصر | C75: كراش بن خولة | D75: أستاذ التعليم العالي | E75: بن علي لامية | F75: بولعروق سعيدة | G75: بوزيان أحمد | H75: أستاذ التعليم العالي | I75: مكيكة محمد جواد | J75: أستاذ التعليم العالي | K75: دراسات نقدية | L75: نقد حديث ومعاصر
A76: 31005 | B76: فلسفة الفقر في كتاب المساكين - لمصطفى صادق الرافعي - | C76: مهيدي منصور | D76: أستاذ التعليم العالي | E76: بلقاسم شمس الدين | F76: /// | G76: بولحراص محمد | H76: أستاذ التعليم العالي | I76: سبع بلمرسلي | J76: أستاذ التعليم العالي | K76: دراسات نقدية | L76: نقد حديث ومعاصر
A77: 31006 | B77: تهافت الأنساق في نقد ما بعدالحداثة - قراءة في بعض النماذج النقدية | C77: مهيدي منصور | D77: أستاذ التعليم العالي | E77: بن تيجيني لهام | F77: زريق نوال | G77: مزيلط محمد | H77: أستاذ التعليم العالي | I77: صوالح محمد | J77: أستاذ محاضر - أ - | K77: دراسات نقدية | L77: نقد حديث ومعاصر
A78: 31007 | B78: قراءة فنية في ديوان بوح الشجون بلسان الملحون للشاعر أحمد بوزيان | C78: مهيدي منصور | D78: أستاذ التعليم العالي | E78: جدلة امحمد | F78: حكوم فاطمية الزهراء | G78: بوزيان أحمد | H78: أستاذ محاضر - ب - | I78: كراش بن خولة | J78: أستاذ محاضر - أ - | K78: دراسات نقدية | L78: نقد حديث ومعاصر
A79: 31008 | B79: فن الترسل في التراث العربي - البنيات و الأشكال | C79: دبيح محمد | D79: أستاذ التعليم العالي | E79: فرحات علال | F79: /// | G79: بوشريحة ابراهيم | H79: أستاذ محاضر - أ - | I79: بلعجين سفيان | J79: أستاذ التعليم العالي | K79: دراسات نقدية | L79: نقد حديث ومعاصر
A80: 31009 | B80: فن الترسل في الأدب العربي الحديث - دراسة أجناسية | C80: دبيح محمد | D80: أستاذ التعليم العالي | E80: زوبيدة جهيدة | F80: حدو نفيسة | G80: مكيكة محمد جواد | H80: أستاذ محاضر - أ - | I80: خروبي بلقاسم | J80: أستاذ التعليم العالي | K80: دراسات نقدية | L80: نقد حديث ومعاصر
...

Sheet الاحصائيات
A5: الرقم | B5: الاسم واللقب | C5: الشعبة | D5: الاشراف | I5: رئاسة الجلسات | N5: عضوية المناقشة | S5: المجموع
D6: لسانيات | E6: تعليمية | F6: أدب | G6: نقد | H6: مج | I6: لسانيات | J6: تعليمية | K6: أدب | L6: نقد | M6: مج | N6: لسانيات | O6: تعليمية | P6: أدب | Q6: نقد | R6: مج
A8: 5 | B8: بالول احمد | C8: دراسات لغوية | H8: =SUM(D8:G8) -> 0 | I8: 1 | J8: 2 | M8: =SUM(I8:L8) -> 3 | O8: 2 | R8: =SUM(N8:Q8) -> 2 | S8: =SUM(R8,M8,H8) -> 5 | T8: 1
A9: 8 | B9: بلقاسم عيسى | C9: دراسات لغوية | D9: 4 | H9: =SUM(D9:G9) -> 4 | J9: 1 | M9: =SUM(I9:L9) -> 1 | R9: =SUM(N9:Q9) -> 0 | S9: =SUM(R9,M9,H9) -> 5 | T9: 2
A10: 14 | B10: بن شريف محمد | C10: دراسات لغوية | H10: =SUM(D10:G10) -> 0 | I10: 2 | J10: 1 | M10: =SUM(I10:L10) -> 3 | N10: 2 | R10: =SUM(N10:Q10) -> 2 | S10: =SUM(R10,M10,H10) -> 5 | T10: 3
A11: 15 | B11: بن فريحة عبد الصمد | C11: دراسات لغوية | H11: =SUM(D11:G11) -> 0 | I11: 1 | J11: 2 | M11: =SUM(I11:L11) -> 3 | O11: 2 | R11: =SUM(N11:Q11) -> 2 | S11: =SUM(R11,M11,H11) -> 5 | T11: 4
A12: 24 | B12: بوكلخة صورية | C12: دراسات لغوية | H12: =SUM(D12:G12) -> 0 | I12: 1 | J12: 1 | M12: =SUM(I12:L12) -> 2 | N12: 1 | O12: 2 | R12: =SUM(N12:Q12) -> 3 | S12: =SUM(R12,M12,H12) -> 5 | T12: 5
A13: 28 | B13: جبالي فتيحة | C13: دراسات لغوية | E13: 3 | H13: =SUM(D13:G13) -> 3 | J13: 2 | M13: =SUM(I13:L13) -> 2 | R13: =SUM(N13:Q13) -> 0 | S13: =SUM(R13,M13,H13) -> 5 | T13: 6
A14: 30 | B14: حاجي زوليخة | C14: دراسات لغوية | E14: 3 | H14: =SUM(D14:G14) -> 3 | J14: 1 | M14: =SUM(I14:L14) -> 1 | O14: 1 | R14: =SUM(N14:Q14) -> 1 | S14: =SUM(R14,M14,H14) -> 5 | T14: 7
A15: 39 | B15: سبع بلمرسلي | C15: دراسات لغوية | D15: 3 | H15: =SUM(D15:G15) -> 3 | I15: 1 | M15: =SUM(I15:L15) -> 1 | Q15: 1 | R15: =SUM(N15:Q15) -> 1 | S15: =SUM(R15,M15,H15) -> 5 | T15: 8
A16: 46 | B16: طيبي نعيمة | C16: دراسات لغوية | H16: =SUM(D16:G16) -> 0 | M16: =SUM(I16:L16) -> 0 | N16: 4 | O16: 1 | R16: =SUM(N16:Q16) -> 5 | S16: =SUM(R16,M16,H16) -> 5 | T16: 9
A17: 77 | B17: عرابي غالية | C17: دراسات لغوية | H17: =SUM(D17:G17) -> 0 | M17: =SUM(I17:L17) -> 0 | N17: 3 | O17: 2 | R17: =SUM(N17:Q17) -> 5 | S17: =SUM(R17,M17,H17) -> 5 | T17: 10
A18: 61 | B18: مرضي مصطفى | C18: دراسات لغوية | H18: =SUM(D18:G18) -> 0 | I18: 1 | J18: 1 | M18: =SUM(I18:L18) -> 2 | N18: 1 | O18: 1 | Q18: 1 | R18: =SUM(N18:Q18) -> 3 | S18: =SUM(R18,M18,H18) -> 5 | T18: 11
A19: 65 | B19: منقور صلاح الدين | C19: دراسات لغوية | H19: =SUM(D19:G19) -> 0 | I19: 1 | J19: 1 | L19: 1 | M19: =SUM(I19:L19) -> 3 | N19: 1 | O19: 1 | R19: =SUM(N19:Q19) -> 2 | S19: =SUM(R19,M19,H19) -> 5 | T19: 12
A20: 1 | B20: احميدة مداني | C20: دراسات لغوية | H20: =SUM(D20:G20) -> 0 | J20: 1 | M20: =SUM(I20:L20) -> 1 | N20: 1 | O20: 2 | R20: =SUM(N20:Q20) -> 3 | S20: =SUM(R20,M20,H20) -> 4 | T20: 13
A21: 2 | B21: العامي حفيظة | C21: دراسات لغوية | D21: 2 | H21: =SUM(D21:G21) -> 2 | I21: 1 | M21: =SUM(I21:L21) -> 1 | O21: 1 | R21: =SUM(N21:Q21) -> 1 | S21: =SUM(R21,M21,H21) -> 4 | T21: 14
A22: 9 | B22: بلقنيشي علي | C22: دراسات لغوية | D22: 1 | E22: 2 | H22: =SUM(D22:G22) -> 3 | J22: 1 | M22: =SUM(I22:L22) -> 1 | R22: =SUM(N22:Q22) -> 0 | S22: =SUM(R22,M22,H22) -> 4 | T22: 15
A23: 12 | B23: بن جلول مختار | C23: دراسات لغوية | D23: 2 | H23: =SUM(D23:G23) -> 2 | I23: 2 | M23: =SUM(I23:L23) -> 2 | R23: =SUM(N23:Q23) -> 0 | S23: =SUM(R23,M23,H23) -> 4 | T23: 16
A24: 17 | B24: بن يحي صحراوي | C24: دراسات لغوية | E24: 3 | H24: =SUM(D24:G24) -> 3 | J24: 1 | M24: =SUM(I24:L24) -> 1 | R24: =SUM(N24:Q24) -> 0 | S24: =SUM(R24,M24,H24) -> 4 | T24: 17
A25: 26 | B25: بوهنوش فاطمة | C25: دراسات لغوية | D25: 2 | H25: =SUM(D25:G25) -> 2 | I25: 2 | M25: =SUM(I25:L25) -> 2 | R25: =SUM(N25:Q25) -> 0 | S25: =SUM(R25,M25,H25) -> 4 | T25: 18
A26: 31 | B26: حدوارة عمر | C26: دراسات لغوية | H26: =SUM(D26:G26) -> 0 | I26: 3 | M26: =SUM(I26:L26) -> 3 | N26: 1 | R26: =SUM(N26:Q26) -> 1 | S26: =SUM(R26,M26,H26) -> 4 | T26: 19
A27: 32 | B27: حسيني بلقاسم | C27: دراسات لغوية | E27: 1 | H27: =SUM(D27:G27) -> 1 | I27: 1 | J27: 1 | M27: =SUM(I27:L27) -> 2 | O27: 1 | R27: =SUM(N27:Q27) -> 1 | S27: =SUM(R27,M27,H27) -> 4 | T27: 20
A28: 33 | B28: حميداني عيسى | C28: دراسات لغوية | H28: =SUM(D28:G28) -> 0 | J28: 2 | M28: =SUM(I28:L28) -> 2 | O28: 2 | R28: =SUM(N28:Q28) -> 2 | S28: =SUM(R28,M28,H28) -> 4 | T28: 21
A29: 38 | B29: زمام نبيلة | C29: دراسات لغوية | H29: =SUM(D29:G29) -> 0 | M29: =SUM(I29:L29) -> 0 | N29: 1 | O29: 3 | R29: =SUM(N29:Q29) -> 4 | S29: =SUM(R29,M29,H29) -> 4 | T29: 22
A30: 49 | B30: عدة قادة | C30: دراسات لغوية | E30: 1 | H30: =SUM(D30:G30) -> 1 | J30: 2 | L30: 1 | M30: =SUM(I30:L30) -> 3 | R30: =SUM(N30:Q30) -> 0 | S30: =SUM(R30,M30,H30) -> 4 | T30: 23
A31: 50 | B31: عزوز ميلود | C31: دراسات لغوية | D31: 3 | H31: =SUM(D31:G31) -> 3 | J31: 1 | M31: =SUM(I31:L31) -> 1 | R31: =SUM(N31:Q31) -> 0 | S31: =SUM(R31,M31,H31) -> 4 | T31: 24
A32: 52 | B32: عياد آمال | C32: دراسات لغوية | H32: =SUM(D32:G32) -> 0 | M32: =SUM(I32:L32) -> 0 | N32: 3 | O32: 1 | R32: =SUM(N32:Q32) -> 4 | S32: =SUM(R32,M32,H32) -> 4 | T32: 25
A33: 53 | B33: فارز فاطيمة | C33: دراسات لغوية | E33: 3 | H33: =SUM(D33:G33) -> 3 | J33: 1 | M33: =SUM(I33:L33) -> 1 | R33: =SUM(N33:Q33) -> 0 | S33: =SUM(R33,M33,H33) -> 4 | T33: 26
A34: 54 | B34: قاسم قادة | C34: دراسات لغوية | E34: 2 | H34: =SUM(D34:G34) -> 2 | J34: 1 | M34: =SUM(I34:L34) -> 1 | O34: 1 | R34: =SUM(N34:Q34) -> 1 | S34: =SUM(R34,M34,H34) -> 4 | T34: 27
A35: 68 | B35: موفق عبد القادر | C35: دراسات لغوية | E35: 1 | H35: =SUM(D35:G35) -> 1 | J35: 2 | M35: =SUM(I35:L35) -> 2 | O35: 1 | R35: =SUM(N35:Q35) -> 1 | S35: =SUM(R35,M35,H35) -> 4 | T35: 28
A36: 69 | B36: ميس سعاد | C36: دراسات لغوية | D36: 1 | H36: =SUM(D36:G36) -> 1 | I36: 1 | M36: =SUM(I36:L36) -> 1 | N36: 1 | O36: 1 | R36: =SUM(N36:Q36) -> 2 | S36: =SUM(R36,M36,H36) -> 4 | T36: 29
A37: 70 | B37: نجادي بوعمامة | C37: دراسات لغوية | E37: 2 | H37: =SUM(D37:G37) -> 2 | I37: 1 | J37: 1 | M37: =SUM(I37:L37) -> 2 | R37: =SUM(N37:Q37) -> 0 | S37: =SUM(R37,M37,H37) -> 4 | T37: 30
A38: 73 | B38: يحياوي عامر | C38: دراسات لغوية | D38: 3 | H38: =SUM(D38:G38) -> 3 | I38: 1 | M38: =SUM(I38:L38) -> 1 | R38: =SUM(N38:Q38) -> 0 | S38: =SUM(R38,M38,H38) -> 4 | T38: 31
A39: 74 | B39: يعقوب الزهرة | C39: دراسات لغوية | H39: =SUM(D39:G39) -> 0 | I39: 1 | M39: =SUM(I39:L39) -> 1 | N39: 2 | O39: 1 | R39: =SUM(N39:Q39) -> 3 | S39: =SUM(R39,M39,H39) -> 4 | T39: 32
A40: 19 | B40: بوزيان أحمد | F40: 3 | H40: =SUM(D40:G40) -> 3 | K40: 1 | L40: 3 | M40: =SUM(I40:L40) -> 4 | R40: =SUM(N40:Q40) -> 0 | S40: =SUM(R40,M40,H40) -> 7 | T40: 33
A41: 11 | B41: بلمهل عبد الهادي | E41: 2 | G41: 1 | H41: =SUM(D41:G41) -> 3 | K41: 2 | M41: =SUM(I41:L41) -> 2 | Q41: 1 | R41: =SUM(N41:Q41) -> 1 | S41: =SUM(R41,M41,H41) -> 6 | T41: 34
A42: 4 | B42: باقل دنيا | F42: 3 | H42: =SUM(D42:G42) -> 3 | M42: =SUM(I42:L42) -> 0 | P42: 2 | R42: =SUM(N42:Q42) -> 2 | S42: =SUM(R42,M42,H42) -> 5 | T42: 35
A43: 36 | B43: دبيح محمد | G43: 3 | H43: =SUM(D43:G43) -> 3 | K43: 1 | M43: =SUM(I43:L43) -> 1 | P43: 1 | R43: =SUM(N43:Q43) -> 1 | S43: =SUM(R43,M43,H43) -> 5 | T43: 36
A44: 41 | B44: شريط رابح | F44: 2 | H44: =SUM(D44:G44) -> 2 | K44: 1 | L44: 1 | M44: =SUM(I44:L44) -> 2 | P44: 1 | R44: =SUM(N44:Q44) -> 1 | S44: =SUM(R44,M44,H44) -> 5 | T44: 37
A45: 43 | B45: شريفي فاطمة | F45: 3 | H45: =SUM(D45:G45) -> 3 | K45: 1 | M45: =SUM(I45:L45) -> 1 | P45: 1 | R45: =SUM(N45:Q45) -> 1 | S45: =SUM(R45,M45,H45) -> 5 | T45: 38
...

Sheet محضر المناقشة
A1: الجمهورية الجزائرية الديمقراطية الشعبية
A2: وزارة التعليم العالي والبحث العلمي
A3: جامعة ابن خلدون ــــ تيارت ـــــ
A4: كلية الآداب واللغات
A5: قسم اللغة العربية وآدابها | E5: الموسم الجامعي : 2023/2024
C6: محضر مناقشة مذكرة ماستر
A8: رقم المذكرة : / | B8: 12007 | C8: /2024
A9: اسم ولقب الطالب (ة) : | C9: =VLOOKUP(B8,'كل التخصصات'!A3:O87,5,1) -> ميساوي فتيحة | E9: تاريخ المناقشة : / | G9: =VLOOKUP(B8,'كل التخصصات'!A3:O87,13,1) -> 0
C10: =VLOOKUP(B8,'كل التخصصات'!A3:O87,6,1) -> // | E10: التوقيت : / | G10: =VLOOKUP(B8,'كل التخصصات'!A3:O87,14,1) -> 0
A11: مسجل بانتظام في السنة الثانية ماستر : / | E11: مكان المناقشة : / | G11: =VLOOKUP(B8,'كل التخصصات'!A3:O87,15,1) -> 0
B12: الشعبة : | C12: =VLOOKUP(B8,'كل التخصصات'!A3:O87,11,1) -> دراسات لغوية
B13: التخصص : | C13: =VLOOKUP(B8,'كل التخصصات'!A3:O87,12,1) -> تعليمية اللغات
A14: عنوان المذكرة : | B14: =VLOOKUP(B8,'كل التخصصات'!A3:O87,2,1) -> محتوى النصوص و استراتيجية تحليلها و أثرها في تحقيق الكفاءة القاعدية _مستوى الطور المتوسط انموذجا_
B15: ناقش (ت) علنا أمام لجنة المناقشة المكونة من الأساتذة : /
A16: أعضاء اللجنة | B16: الاسم واللقب | D16: الربتة | E16: الجامعة | G16: الامضاء
A17: رئيس | B17: =VLOOKUP(B8,'كل التخصصات'!A3:O87,7,1) -> قاسم قادة | D17: =VLOOKUP(B8,'كل التخصصات'!A3:O87,8,1) -> أستاذ التعليم العالي | E17: جامعة ابن خلدون ـــ تيارت ـــ
A18: مقرر | B18: =VLOOKUP(B8,'كل التخصصات'!A3:O87,3,1) -> فارز فاطمة | D18: =VLOOKUP(B8,'كل التخصصات'!A3:O87,4,1) -> استاذ التعليم العالي | E18: جامعة ابن خلدون ـــ تيارت ـــ
A19: مناقش | B19: =VLOOKUP(B8,'كل التخصصات'!A3:O87,9,1) -> بالول أحمد | D19: =VLOOKUP(B8,'كل التخصصات'!A3:O87,10,1) -> أستاذ التعليم العالي | E19: جامعة ابن خلدون ـــ تيارت ـــ
A20: بعد المداولات فررت اللجنة منح التقدير التالي :
A21: علامة العضو المناقش : ....../20 -- علامة رئيس الجلسة : ........./ 20 -- العلامة النهائية : .......... /20
A23: بتقدير : / | B23: مقبول 10 -12 | E23: جيد 14 -16
B25: قريب من الجيد 12 -14 | E25: جيد جدا 16 -18
B27: متاز 18 -20
C28: تيارت في : / | D28: =TODAY() -> 46148 | F28: الموافق | G28: =TODAY() -> 46148
A29: رئيس اللجنة | F29: رئيس القسم

Sheet لسانيات الخطاب
B1: السنة الثانية ماستر لسانيات الخطاب 2024/2023 | T1: الفوج1
A2: الرقم | B2: اللقب | C2: الإسم | T2: البحث | U2: الملاحظة | V2: الحالة
A3: 1 | B3: عابدي | C3: محمد | V3: لم يسند إليه موضوع الأطروحة
A4: 2 | B4: عابد | C4: عبد الجليل | V4: مسند إليه موضوع الاطروحة
A5: 3 | B5: ايت قنون | C5: فاطيمة | V5: مسند إليه موضوع الاطروحة
A6: 4 | B6: بحرية | C6: منال | V6: مسند إليه موضوع الاطروحة
A7: 5 | B7: بلهواري | C7: مامة | V7: لم يسند إليه موضوع الأطروحة
A8: 6 | B8: بن جامعة | C8: ميمونة | V8: مسند إليه موضوع الاطروحة
A9: 7 | B9: بن فراحة | C9: خيرة | V9: مسند إليه موضوع الاطروحة
A10: 8 | B10: بن قراد | C10: أحمد | V10: مسند إليه موضوع الاطروحة
A11: 9 | B11: بن حامد | C11: أمينة | V11: مسند إليه موضوع الاطروحة
A12: 10 | B12: بن ماحية | C12: مامة | V12: مسند إليه موضوع الاطروحة
A13: 11 | B13: بن سعدي | C13: سعاد | V13: لم يسند إليه موضوع الأطروحة
A14: 12 | B14: بن طراد | C14: العيد | V14: مسند إليه موضوع الاطروحة
... A44: 42 | B44: زياني | C44: اميرة نريمان | V44: مسند إليه موضوع الاطروحة

Sheet مواضيع لسانيات الخطاب
A1: الرقم | B1: الموضوع | C1: الأستاذ المشرف | D1: اسم الطالب الأول | E1: اسم الطالب الثاني
A2: 11001 | B2: تجلّيات الحجاج في رسائل الحسن البصري إلى الخليفة عمر بن عبد العزيز (رسالة الإمام العادل أنموذجا) | C2: بلقنيشي علي
A3: 11002 | B3: بلاغة الأبنية الصرفية في النص القرآني – آيات المنافقين أنموذجا – | C3: بلقنيشي علي | D3: واضح حسيبة
A4: 11003 | B4: آليات التّلوين الصّوتي وأثرها في إنتاج الدّلالة (دراسة في سورة التّوبة) | C4: بلقنيشي علي
A5: 11004 | B5: أسلوب النهي بين التركيب والدلالة في القرٱن الكربم | C5: بلقاسم عيسى | D5: بن حامد أمينة
A6: 11005 | B6: ما التعجبية بين الدلالة والتركيب في القرٱن الكريم | C6: بلقاسم عيسى | D6: درقاوي وئام
A7: 11006 | B7: دلالة اسم المفعول في القرآن الكريم سورة البقرة انموذجا | C7: بلقاسم عيسى | D7: بن طراد العيد | E7: بن قراد أحمد
A8: 11007 | B8: دلالة التربية الروحية في القرآن الكريم ( سورة لقمان أنموذجا ) | C8: بلقاسم عيسى | D8: بن جامعة ميمونة
A9: 11008 | B9: المنزع العقلي في كتاب دلائل الإعجاز لعبد القاهر الجرحاني | C9: عزوز ميلود | D9: قاسيمي الحسني يسرى | E9: قصاب إكرام
A10: 11009 | B10: بلاغة الصمت في مخاطبات النفري | C10: عزوز ميلود | D10: فاطمي جلول
A11: 11010 | B11: التلوث اللساني في خطاب المقالات العلمية المنشورة باللغة العربية مقاربة تحليلية لمحتوى المنصة الجزائرية للمجلات العلمية (Asjp) مجلة فصل الخطاب منذ تصنيفها مجلة فصل الخطاب منذ تصنيفها | C11: عزوز ميلود | D11: ياسيني نصيرة | E11: مداح منال
A12: 11011 | B12: هندسة الخطاب التعليمي الاِفتراضي وتداولية أفعال التحفيز نظرية كيلر على عينة من الطلبة الجامعيين | C12: بن جلول مختار | D12: عابد عبد الجليل
A13: 11012 | B13: الصراع الفكري في الخطابات الثنائية وأساليبه الإقناعية - دراسة نماذج قرآنية | C13: بن جلول مختار
A14: 11013 | B14: بنيات الخطاب الأنثوي في النص القرآني - خطابات مريم عليها السلام أنموذجا - | C14: بن جلول مختار | D14: بوسنة رزيقة | E14: مصطفاوي مختارية
A15: 11014 | B15: لغة الخطاب التواصلي في المجتمع الجزائري - نماذج مختلفة | C15: ميس سعاد | D15: محمودي ماريا
A16: 11015 | B16: مصطلحات لسانيات النص وتحليل الخطاب دراسة تقويمية لمعجم المصطلحات الأساسية في لسانيات النص وتحليل الخطاب نعمان بوقرة | C16: ميس سعاد | D16: لحمر خديجة | E16: غول أحلام
A17: 11016 | B17: الروابط النصية في مدونة وحي القلم للرافعي - نماذج من النثريات الموجودة في الكتاب | C17: ميس سعاد
A18: 11017 | B18: الأبعاد الدلالية لمقولة الربط في نظام الجملة القرآنية | C18: بوهنوش فاطمة | D18: لزعر محمد
A19: 11018 | B19: مظاهر الوصفية في التفكير النحوي وعلاقتها بالدرس اللغوي الحديث | C19: بوهنوش فاطمة
A20: 11019 | B20: خطاب الاضمار في اسلوب التقدير الاسمي ودلالته في القران الكريم ( قراءة في كتاب معاني القرآن للاخفش الاوسط انموذجا ) | C20: بوهنوش فاطمة
A21: 11020 | B21: أشكال التداخل الصرفي في القراءات القرآنية - دراسة في بنية الأفعال - | C21: بالول أحمد
A22: 11021 | B22: جهود اللغويين المحدثين في إبراز مظاهر الإعجاز اللغوي في القرآن الكريم | C22: بالول أحمد
A23: 11022 | B23: مظاهر التأويل الصوفي في كتب تفسير القرآن تفسير البحر المديد انموذجا | C23: بالول أحمد
A24: 11023 | B24: التغير الدلالي للألفاظ وأثره في المعنى سورة الرحمان أنموذجا | C24: العامي حفيظة | D24: بوجمعة هاجر | E24: نونة كريمة
A25: 11024 | B25: الوظيفة التواصلية في سورة القمر وأثرها الإبلاغ | C25: العامي حفيظة | D25: بن ماحية مامة | E25: بحرية منال
A26: 11025 | B26: ٣. الدلالة التركيبية في سورة آل عمران وأثرها في السياق القرآني | C26: العامي حفيظة
A27: 11026 | B27: تجليات البحث البلاغي في كتاب معاني القرآن للفراء (207هـ) قراءة في الجزء الأوّل | C27: سبع بلمرسلي | D27: مقاديم سعاد | E27: زيادي فاطمة زهرة
A28: 11027 | B28: بلاغة أسلوب الاحتراس في القرآن الكريم من خلال تفسير (التحرير والتنوير) للشيخ ابن عاشور | C28: سبع بلمرسلي | D28: ناجم أمال
A29: 11028 | B29: حجاجية التمثيل في الحديث النبوي الشريف -دراسة لنماذج مختارة من صحيحي البخاري ومسلم- | C29: سبع بلمرسلي | D29: خيثور خديجة | E29: آيت قنون فاطيمة
A30: 11029 | B30: الدلالة التركيبية في ديوان "طال الشتات" لمريد البرغوثي | C30: يحياوي عامر | D30: زياني أميرة ناريمان | E30: رابح نور الهدى
A31: 11030 | B31: ظاهرة اللغة والمجاز في فكر عبد الوهاب المسيري- دراسة تحليلية لكتابه اللغة والمجاز بين التوحيد ووحدة الوجود- | C31: يحياوي عامر | D31: بن فراحة خيرة | E31: بوزياني عائشة
A32: 11031 | B32: التفكير اللساني في كتاب "المنوال النحوي العربي قراءة لسانية جديدة" لعز الدين المجدوب | C32: يحياوي عامر | D32: بومدين أمينة | E32: مناد أحلام
A33: 11032 | B33: جهود علماء الجزائر في تسيير الدرس النحوي/اختيار نموذج. | C33: بلحسين محمد
A34: 11033 | B34: صيغة افعل في القرآن الكريم/دراسة صرفية دلالية.اختيار سورة | C34: بلحسين محمد
A35: 11034 | B35: أثر علم الكلام ( في الدرس النحوي العربي ) بين التقعيد والتعقيد. | C35: بلحسين محمد
A36: 11035 | B36: دلالة المحكَم والمتشابِه في القرآن الكريم من خلال نماذج مختارة | C36: بن فريحة عبد الصّمد
A37: 11036 | B37: البعد الدّلالي للتقديم والتأخير في القرآن الكريم من خلال نماذج مختارة | C37: بن فريحة عبد الصّمد
A38: 11037 | B38: دلالة الفصل والوصل مواضعه ومحسناته | C38: بن فريحة عبد الصّمد
A39: 11038 | B39: دلالة المشترك اللفظي والتضاد | C39: بن فريحة عبد الصّمد
A40: 11039 | B40: المشترك اللفظي عند القدامى والمحدثين غايته وفائدته موقف العلماء من وجوده | C40: بن فريحة عبد الصّمد
...
